<robot name="morpheus">
	<link name="base_link" />
	<link name="axis" />
	<link name="arm" />
	<link name="forearm"/>
	<link name="hand"/>
	
	<joint name="joint1" type="continuous">
		<parent link="base_link"/>
		<child link="axis"/>
		<origin xyz="0.3 0 0.1" rpy="0 0 0"/>
		<axis xyz="0 0 1" />
	</joint>
	
	<joint name="joint2" type="continuous">
		<parent link="axis" />
		<child link="arm" />
		<origin xyz="0.0 0 0.0" rpy="0 0 0" />
		<axis xyz="0 1 0" />
	</joint>
	
	<joint name="joint3" type="continuous">
		<parent link="arm"/>
		<child link="forearm"/>
		<origin xyz="0.2 0 0.2" rpy="0 0.0 0" />
		<axis xyz="0 1 0" />
	</joint>
	
	<joint name="joint4" type="continuous">
		<parent link="forearm"/>
		<child link="wrist"/>
		<origin xyz="0.2 0 -0.2" rpy="0 0.0 0" />
		<axis xyz="0 1 0" />
	</joint>

	<joint name="joint5" type="continuous">
		<parent link="wrist"/>
		<child link="hand"/>
		<origin xyz="0.0 0 0.0" rpy="0 0.0 0" />
		<axis xyz="0 0 1" />
	</joint>
</robot>
